Workbook

Sheet Read_Me
A1: VIA monthly project reporting | BLANK INPUT TEMPLATE
A2: Do not publish without source review. This workbook contains no client passwords.
A3: Topic | B3: Instructions
A4: Template version | B4: VIA-REPORT-EXCEL-1.0; one workbook = one project + one reporting month.
A5: Workbook purpose | B5: Filled from the Mughsayl web demo. ALL entered values are DUMMY DATA, not approved project figures.
A6: Current app compatibility | B6: Direct .xlsx import still needs implementation. Do not upload this workbook to the existing CSV-only importer. This workbook defines the proposed Excel import contract.
A7: Start here | B7: Complete Project, Contract_Dates and Progress_Finance. Then complete relevant repeating tables.
A8: Numbers | B8: Enter 95 for 95 percent; percent cells display 95.00%. Enter amounts as numbers, no currency text. Use zero only when explicitly reported.
A9: Missing vs not applicable | B9: Leave missing values blank and select Not reported. Use Not applicable only when the source/team confirms it. Never put NA into a numeric cell.
A10: Dates / identifiers | B10: Use real Excel dates. Report month uses its first day only as a month identifier. Store references and telephone numbers as text to preserve leading zeroes.
A11: Manual assets | B11: Upload logo, project layout and four photographs in the app; record captions and asset IDs on Assets. Additional logos, status drawing and source S-curve image have separate slots. No images need to be embedded in Excel.
A12: Schedule | B12: Copy readable monthly numbers from original Excel/source table. Leave future actuals blank. If unreadable, choose Source image and upload the original S-curve. Never estimate plotted values.
A13: Financial semantics | B13: Financial progress, certified amount, paid amount and anticipated payment are distinct. Never substitute one for another.
A14: Scope and layers | B14: Optional if not reported / not applicable. Never invent five quantities or pavement layers to fill a dashboard.
... A23: Project URL | B23: The demo is /demos/mughsayl.html; no live project slug is assigned to this workbook.

Sheet Project
A1: Project
A2: Blue cells: enter data. Keep field keys, headers and sheet names unchanged. Missing numeric data = blank + a status, never invented zero.
A3: Field key | B3: Field label | C3: Value | D3: Unit / type | E3: Requirement | F3: Entry status | G3: Source reference | H3: Instructions / clarification
A4: project_name | B4: Full project name | C4: Construction Works of Mughsayl Road and Bridge | D4: text | E4: Required | F4: Needs review | G4: Mughsayl HTML demo — DUMMY DATA, not an approved report | H4: Copy the approved project title.
A5: project_reference | B5: Project / contract reference | C5: DEMO ONLY / 2026 / 01 | D5: text | E5: If reported | F5: Needs review | G5: Mughsayl HTML demo — DUMMY DATA, not an approved report | H5: Do not invent an identifier.
A6: project_slug | B6: Existing project URL slug | D6: text | E6: Required | F6: Not reported | H6: For later months use the SAME project slug. Set once in the app.
A7: project_type | B7: Project type | C7: Illustrative data — not an approved report | D7: text | E7: Required | F7: Needs review | G7: Mughsayl HTML demo — DUMMY DATA, not an approved report | H7: Internal classification; confirm with project team.
A8: region | B8: Region / governorate | C8: Governorate of Dhofar, Sultanate of Oman | D8: text | E8: Required | F8: Needs review | G8: Mughsayl HTML demo — DUMMY DATA, not an approved report | H8: As printed.
A9: report_month | B9: Reporting month | C9: 46204 | D9: month | E9: Required | F9: Needs review | G9: Mughsayl HTML demo — DUMMY DATA, not an approved report | H9: Enter first day of the report month; displayed as month and year.
A10: report_number | B10: Report number | C10: 17 | D10: text | E10: If reported | F10: Needs review | G10: Mughsayl HTML demo — DUMMY DATA, not an approved report | H10: Printed page number is NOT the report number.
A11: data_as_of | B11: Exact data-as-of date | C11: 46234 | D11: date | E11: Required | F11: Needs review | G11: Mughsayl HTML demo — DUMMY DATA, not an approved report | H11: Confirm exact date; July 2026 alone does not establish 31 July.
A12: revision | B12: Report revision | C12: Rev-01 | D12: text | E12: If reported | F12: Needs review | G12: Mughsayl HTML demo — DUMMY DATA, not an approved report | H12: Do not assume Rev-01.
A13: source_filename | B13: Original report filename | C13: http://localhost:8080/demos/mughsayl.html | D13: text | E13: Required | F13: Needs review | G13: Mughsayl HTML demo — DUMMY DATA, not an approved report | H13: Source PDF retained for review.
A14: brief | B14: Project brief | C14: Bridge and approach road works | D14: text | E14: Required | F14: Needs review | G14: Mughsayl HTML demo — DUMMY DATA, not an approved report | H14: Keep full scope and significant qualifications.
A15: prepared_by | B15: Prepared by | D15: text | E15: Internal | F15: Not reported | H15: Name of person entering this workbook.
A16: checked_by | B16: Checked by | D16: text | E16: Internal | F16: Not reported | H16: Reviewer name. A workbook name is not an authenticated app approval.
A17: checked_date | B17: Checked date | D17: date | E17: Internal | F17: Not reported | H17: Actual date reviewed.

Sheet Contract_Dates
A1: Contract Dates
A2: Blue cells: enter data. Keep field keys, headers and sheet names unchanged. Missing numeric data = blank + a status, never invented zero.
A3: Field key | B3: Field label | C3: Value | D3: Unit / type | E3: Requirement | F3: Entry status | G3: Source reference | H3: Instructions / clarification
A4: currency | B4: Currency | C4: R.O. | D4: text | E4: Required | F4: Needs review | G4: Mughsayl HTML demo — DUMMY DATA, not an approved report | H4: Applies to monetary figures.
A5: original_ex_contingency | B5: Original contract excluding contingency | D5: amount | E5: Required | F5: Not reported | H5: Preserve three decimal places.
A6: contingency | B6: Contingency | D6: amount | E6: If reported | F6: Not reported | H6: Sample prints Nil; numeric zero is its interpretation, subject to review.
A7: original_inc_contingency | B7: Original contract including contingency | D7: amount | E7: Required | F7: Not reported | H7: Do not sum variation totals together.
A8: contract_with_vo_1 | B8: Contract with VO.1 and contingency | D8: amount | E8: If applicable | F8: Not reported | H8: Sample prints NA: keep value blank and select Not applicable.
A9: contract_with_vo_2 | B9: Contract with VO.2 and contingency | D9: amount | E9: If applicable | F9: Not reported | H9: Sample prints NA: keep value blank and select Not applicable.
A10: contract_with_vo_3 | B10: Contract with VO.3 and contingency | D10: amount | E10: If applicable | F10: Not reported | H10: Sample prints NA: keep value blank and select Not applicable.
A11: contract_with_vo_4 | B11: Contract with VO.4 and contingency | D11: amount | E11: If applicable | F11: Not reported | H11: Sample prints NA: keep value blank and select Not applicable.
A12: dashboard_contract_value | B12: Approved contract value used on dashboard | C12: 34844452 | D12: amount | E12: Required | F12: Needs review | G12: Mughsayl HTML demo — DUMMY DATA, not an approved report | H12: Reviewer selects the applicable current contract basis; do not guess.
A13: contract_basis | B13: Basis of dashboard contract value | C13: Demo dashboard contract value; original/variation breakdown not supplied | D13: text | E13: Required | F13: Needs review | G13: Mughsayl HTML demo — DUMMY DATA, not an approved report | H13: For example: original including contingency, or approved VO.2 total.
A14: award_date | B14: Awarding date | C14: 45658 | D14: date | E14: Required | F14: Needs review | G14: Mughsayl HTML demo — DUMMY DATA, not an approved report | H14: Enter a real Excel date.
A15: mobilization_days | B15: Mobilization period | C15: 60 | D15: days | E15: If reported | F15: Needs review | G15: Mughsayl HTML demo — DUMMY DATA, not an approved report | H15: Not automatically added to construction duration.
A16: construction_days | B16: Original construction period | C16: 912 | D16: days | E16: Required | F16: Needs review | G16: Mughsayl HTML demo — DUMMY DATA, not an approved report | H16: Sample: 669 days.
A17: start_date | B17: Start of construction | C17: 45718 | D17: date | E17: Required | F17: Needs review | G17: Mughsayl HTML demo — DUMMY DATA, not an approved report | H17: As printed; reconcile with duration separately.
A18: completion_date | B18: Contract completion date | C18: 46629 | D18: date | E18: Required | F18: Needs review | G18: Mughsayl HTML demo — DUMMY DATA, not an approved report | H18: Original contractual completion date.
A19: construction_days_with_vos | B19: Construction period with VOs | D19: days | E19: If applicable | F19: Not reported | H19: Sample prints a dash; do not interpret this as zero.
A20: completion_date_with_vos | B20: Completion date with VOs | D20: date | E20: If applicable | F20: Not reported | H20: Leave blank if unreported.
A21: elapsed_days | B21: Elapsed time | C21: 517 | D21: days | E21: Required | F21: Needs review | G21: Mughsayl HTML demo — DUMMY DATA, not an approved report | H21: Reported duration; check against remaining days.
A22: remaining_days | B22: Remaining period | C22: 395 | D22: days | E22: Required | F22: Needs review | G22: Mughsayl HTML demo — DUMMY DATA, not an approved report | H22: Do not calculate from today; this is a monthly snapshot.
A23: expected_completion | B23: Expected completion date | C23: 46629 | D23: date | E23: Required | F23: Needs review | G23: Mughsayl HTML demo — DUMMY DATA, not an approved report | H23: Separate from original completion date.

Sheet Progress_Finance
A1: Progress Finance
A2: Blue cells: enter data. Keep field keys, headers and sheet names unchanged. Missing numeric data = blank + a status, never invented zero.
A3: Field key | B3: Field label | C3: Value | D3: Unit / type | E3: Requirement | F3: Entry status | G3: Source reference | H3: Instructions / clarification
A4: physical_planned | B4: Bridge & road cumulative planned progress | C4: 47.95 | D4: percent | E4: Required | F4: Needs review | G4: Mughsayl HTML demo — DUMMY DATA, not an approved report | H4: Enter 95 for 95%, NOT 0.95.
A5: physical_actual | B5: Bridge & road cumulative actual progress | C5: 40.94 | D5: percent | E5: Required | F5: Needs review | G5: Mughsayl HTML demo — DUMMY DATA, not an approved report | H5: Do not substitute financial progress.
A6: physical_variance_reported | B6: Reported physical ahead / delay | C6: -7.01 | D6: signed percent | E6: If reported | F6: Needs review | G6: Mughsayl HTML demo — DUMMY DATA, not an approved report | H6: Keep printed sign; calculated actual-minus-planned appears in Checks.
A7: arches_planned | B7: Arches cumulative planned progress | D7: percent | E7: If reported | F7: Not reported | H7: Arches column is blank in sample. Activity-row figures belong on Activities.
A8: arches_actual | B8: Arches cumulative actual progress | D8: percent | E8: If reported | F8: Not reported | H8: Do not copy overall bridge progress into this column.
A9: monthly_planned | B9: This-month planned physical progress | C9: 3.72 | D9: percent | E9: If reported | F9: Needs review | G9: Mughsayl HTML demo — DUMMY DATA, not an approved report | H9: Leave blank if tiny chart table is unreadable.
A10: monthly_actual | B10: This-month actual physical progress | C10: 1.69 | D10: percent | E10: If reported | F10: Needs review | G10: Mughsayl HTML demo — DUMMY DATA, not an approved report | H10: Never derive by estimating line heights.
A11: financial_planned | B11: Financial cumulative planned progress | D11: percent | E11: Required | F11: Not reported | H11: Independent of physical planned progress.
A12: financial_actual | B12: Financial cumulative actual progress | C12: 33.38 | D12: percent | E12: Required | F12: Needs review | G12: Mughsayl HTML demo — DUMMY DATA, not an approved report | H12: Confirm what this measure represents; do not assume paid / contract.
A13: financial_difference_reported | B13: Printed financial difference | D13: signed percent | E13: If reported | F13: Not reported | H13: Sample prints +4.39 without a minus; actual-minus-planned is -4.39.
A14: financial_difference_basis | B14: Meaning of reported financial difference | D14: text | E14: Needs clarification | F14: Not reported | H14: Confirm whether the source uses planned minus actual.
A15: anticipated_payment | B15: Total payment anticipated | D15: amount | E15: If reported | F15: Not reported | H15: This is NOT total paid or certified amount.
A16: paid_amount | B16: Total actually paid | C16: 10969331 | D16: amount | E16: If reported | F16: Needs review | G16: Mughsayl HTML demo — DUMMY DATA, not an approved report | H16: Not explicitly provided in sample. Keep blank.
A17: certified_amount | B17: Total certified amount | D17: amount | E17: If reported | F17: Not reported | H17: Distinct from anticipated and actually paid amounts.
A18: financial_basis | B18: Definition / denominator of financial percentage | D18: text | E18: Needs clarification | F18: Not reported | H18: Use to determine whether a paid-to-contract comparison is meaningful.
A19: chart_mode | B19: S-curve representation | C19: Verified schedule | D19: text | E19: Required | F19: Needs review | G19: Mughsayl HTML demo — DUMMY DATA, not an approved report | H19: Choose Verified schedule or Source image; sample needs original chart/table.

Sheet Activities
A1: Physical progress of major activities
A2: Percentages are percentage points: 100 = 100%. Above 100 is retained for review, not silently capped.
A3: Activity ID | B3: Activity name | C3: Planned % | D3: Actual % | E3: Printed difference % | F3: Calculated actual-plan | G3: Entry status | H3: Source reference | I3: Notes
A4: activity_01 | B4: Mobilization | C4: 60 | D4: 60 | E4: 0 | F4: =IF(COUNT(C4:D4)=2,D4-C4,"") | G4: Needs review | H4: Mughsayl HTML demo — DUMMY DATA, not an approved report | I4: Dummy activity figures from the demo; not for reporting.
A5: activity_02 | B5: Unclassified Excavation | C5: 62.72 | D5: 71.79 | E5: 9.07 | F5: =IF(COUNT(C5:D5)=2,D5-C5,"") | G5: Needs review | H5: Mughsayl HTML demo — DUMMY DATA, not an approved report | I5: Dummy activity figures from the demo; not for reporting.
A6: activity_03 | B6: Unclassified Str. Excavation | C6: 98.97 | D6: 103.4 | E6: 4.43 | F6: =IF(COUNT(C6:D6)=2,D6-C6,"") | G6: Needs review | H6: Mughsayl HTML demo — DUMMY DATA, not an approved report | I6: Dummy activity figures from the demo; not for reporting.
A7: activity_04 | B7: GSB (Class-B) | C7: 43 | D7: 30 | E7: -13 | F7: =IF(COUNT(C7:D7)=2,D7-C7,"") | G7: Needs review | H7: Mughsayl HTML demo — DUMMY DATA, not an approved report | I7: Dummy activity figures from the demo; not for reporting.
A8: activity_05 | B8: ABC (Class-B) | C8: 45.21 | D8: 24.92 | E8: -20.29 | F8: =IF(COUNT(C8:D8)=2,D8-C8,"") | G8: Needs review | H8: Mughsayl HTML demo — DUMMY DATA, not an approved report | I8: Dummy activity figures from the demo; not for reporting.
A9: activity_06 | B9: Bit. Base Course (Class-B) | C9: 43.94 | D9: 19.72 | E9: -24.22 | F9: =IF(COUNT(C9:D9)=2,D9-C9,"") | G9: Needs review | H9: Mughsayl HTML demo — DUMMY DATA, not an approved report | I9: Dummy activity figures from the demo; not for reporting.
A10: activity_07 | B10: Bit. Wearing (Class-B) | C10: 38.1 | D10: 0 | E10: -38.1 | F10: =IF(COUNT(C10:D10)=2,D10-C10,"") | G10: Needs review | H10: Mughsayl HTML demo — DUMMY DATA, not an approved report | I10: Dummy activity figures from the demo; not for reporting.
A11: activity_08 | B11: Concrete C-15 | C11: 78.38 | D11: 78.68 | E11: 0.3 | F11: =IF(COUNT(C11:D11)=2,D11-C11,"") | G11: Needs review | H11: Mughsayl HTML demo — DUMMY DATA, not an approved report | I11: Dummy activity figures from the demo; not for reporting.
A12: activity_09 | B12: Concrete C-35 | C12: 63.67 | D12: 54.82 | E12: -8.85 | F12: =IF(COUNT(C12:D12)=2,D12-C12,"") | G12: Needs review | H12: Mughsayl HTML demo — DUMMY DATA, not an approved report | I12: Dummy activity figures from the demo; not for reporting.
A13: activity_10 | B13: Steel (any dia.) | C13: 65.59 | D13: 52.2 | E13: -13.39 | F13: =IF(COUNT(C13:D13)=2,D13-C13,"") | G13: Needs review | H13: Mughsayl HTML demo — DUMMY DATA, not an approved report | I13: Dummy activity figures from the demo; not for reporting.
A14: activity_11 | F14: =IF(COUNT(C14:D14)=2,D14-C14,"") | G14: Not reported
A15: activity_12 | F15: =IF(COUNT(C15:D15)=2,D15-C15,"") | G15: Not reported
A16: activity_13 | F16: =IF(COUNT(C16:D16)=2,D16-C16,"") | G16: Not reported
A17: activity_14 | F17: =IF(COUNT(C17:D17)=2,D17-C17,"") | G17: Not reported
A18: activity_15 | F18: =IF(COUNT(C18:D18)=2,D18-C18,"") | G18: Not reported
A19: activity_16 | F19: =IF(COUNT(C19:D19)=2,D19-C19,"") | G19: Not reported
A20: activity_17 | F20: =IF(COUNT(C20:D20)=2,D20-C20,"") | G20: Not reported
A21: activity_18 | F21: =IF(COUNT(C21:D21)=2,D21-C21,"") | G21: Not reported
A22: activity_19 | F22: =IF(COUNT(C22:D22)=2,D22-C22,"") | G22: Not reported
A23: activity_20 | F23: =IF(COUNT(C23:D23)=2,D23-C23,"") | G23: Not reported

Sheet Monthly_Schedule
A1: S-curve | monthly source values
A2: Leave month cells blank until original values are available. Chronological order, one row per month; no invented zero start point.
A3: Month | B3: Monthly planned % | C3: Monthly actual % | D3: Cumulative planned % | E3: Cumulative actual % | F3: Monthly actual-plan | G3: Entry status | H3: Source reference | I3: Notes
A4: 45689 | B4: 0.5 | C4: 0.5 | D4: 0.5 | E4: 0.5 | F4: =IF(COUNT(B4:C4)=2,C4-B4,"") | G4: Needs review | H4: Mughsayl HTML demo — DUMMY DATA, not an approved report | I4: Dummy programme; future actuals intentionally blank.
A5: 45717 | B5: 0.6 | C5: 0.6 | D5: 1.1 | E5: 1.1 | F5: =IF(COUNT(B5:C5)=2,C5-B5,"") | G5: Needs review | H5: Mughsayl HTML demo — DUMMY DATA, not an approved report | I5: Dummy programme; future actuals intentionally blank.
A6: 45748 | B6: 0.8 | C6: 0.8 | D6: 1.9 | E6: 1.9 | F6: =IF(COUNT(B6:C6)=2,C6-B6,"") | G6: Needs review | H6: Mughsayl HTML demo — DUMMY DATA, not an approved report | I6: Dummy programme; future actuals intentionally blank.
A7: 45778 | B7: 1.1 | C7: 1.1 | D7: 3 | E7: 3 | F7: =IF(COUNT(B7:C7)=2,C7-B7,"") | G7: Needs review | H7: Mughsayl HTML demo — DUMMY DATA, not an approved report | I7: Dummy programme; future actuals intentionally blank.
A8: 45809 | B8: 1.5 | C8: 1.5 | D8: 4.5 | E8: 4.5 | F8: =IF(COUNT(B8:C8)=2,C8-B8,"") | G8: Needs review | H8: Mughsayl HTML demo — DUMMY DATA, not an approved report | I8: Dummy programme; future actuals intentionally blank.
A9: 45839 | B9: 1.8 | C9: 1.8 | D9: 6.3 | E9: 6.3 | F9: =IF(COUNT(B9:C9)=2,C9-B9,"") | G9: Needs review | H9: Mughsayl HTML demo — DUMMY DATA, not an approved report | I9: Dummy programme; future actuals intentionally blank.
A10: 45870 | B10: 2.1 | C10: 2.1 | D10: 8.4 | E10: 8.4 | F10: =IF(COUNT(B10:C10)=2,C10-B10,"") | G10: Needs review | H10: Mughsayl HTML demo — DUMMY DATA, not an approved report | I10: Dummy programme; future actuals intentionally blank.
A11: 45901 | B11: 2.5 | C11: 2.5 | D11: 10.9 | E11: 10.9 | F11: =IF(COUNT(B11:C11)=2,C11-B11,"") | G11: Needs review | H11: Mughsayl HTML demo — DUMMY DATA, not an approved report | I11: Dummy programme; future actuals intentionally blank.
A12: 45931 | B12: 2.8 | C12: 2.8 | D12: 13.7 | E12: 13.7 | F12: =IF(COUNT(B12:C12)=2,C12-B12,"") | G12: Needs review | H12: Mughsayl HTML demo — DUMMY DATA, not an approved report | I12: Dummy programme; future actuals intentionally blank.
A13: 45962 | B13: 3.1 | C13: 3.1 | D13: 16.8 | E13: 16.8 | F13: =IF(COUNT(B13:C13)=2,C13-B13,"") | G13: Needs review | H13: Mughsayl HTML demo — DUMMY DATA, not an approved report | I13: Dummy programme; future actuals intentionally blank.
A14: 45992 | B14: 3.4 | C14: 3.4 | D14: 20.2 | E14: 20.2 | F14: =IF(COUNT(B14:C14)=2,C14-B14,"") | G14: Needs review | H14: Mughsayl HTML demo — DUMMY DATA, not an approved report | I14: Dummy programme; future actuals intentionally blank.
A15: 46023 | B15: 3.6 | C15: 3.6 | D15: 23.8 | E15: 23.8 | F15: =IF(COUNT(B15:C15)=2,C15-B15,"") | G15: Needs review | H15: Mughsayl HTML demo — DUMMY DATA, not an approved report | I15: Dummy programme; future actuals intentionally blank.
... A21: 46204 | B21: 3.72 | C21: 1.69 | D21: 47.95 | E21: 40.94 | F21: =IF(COUNT(B21:C21)=2,C21-B21,"") | G21: Needs review | H21: Mughsayl HTML demo — DUMMY DATA, not an approved report | I21: Dummy programme; future actuals intentionally blank.
A22: 46235 | B22: 4 | D22: 51.95 | F22: =IF(COUNT(B22:C22)=2,C22-B22,"") | G22: Needs review | H22: Mughsayl HTML demo — DUMMY DATA, not an approved report | I22: Dummy programme; future actuals intentionally blank.
A23: 46266 | B23: 4.2 | D23: 56.15 | F23: =IF(COUNT(B23:C23)=2,C23-B23,"") | G23: Needs review | H23: Mughsayl HTML demo — DUMMY DATA, not an approved report | I23: Dummy programme; future actuals intentionally blank.
A24: 46296 | B24: 4.4 | D24: 60.55 | F24: =IF(COUNT(B24:C24)=2,C24-B24,"") | G24: Needs review | H24: Mughsayl HTML demo — DUMMY DATA, not an approved report | I24: Dummy programme; future actuals intentionally blank.
A25: 46327 | B25: 4.6 | D25: 65.15 | F25: =IF(COUNT(B25:C25)=2,C25-B25,"") | G25: Needs review | H25: Mughsayl HTML demo — DUMMY DATA, not an approved report | I25: Dummy programme; future actuals intentionally blank.
A26: 46357 | B26: 4.8 | D26: 69.95 | F26: =IF(COUNT(B26:C26)=2,C26-B26,"") | G26: Needs review | H26: Mughsayl HTML demo — DUMMY DATA, not an approved report | I26: Dummy programme; future actuals intentionally blank.
A27: 46388 | B27: 4.5 | D27: 74.45 | F27: =IF(COUNT(B27:C27)=2,C27-B27,"") | G27: Needs review | H27: Mughsayl HTML demo — DUMMY DATA, not an approved report | I27: Dummy programme; future actuals intentionally blank.
A28: 46419 | B28: 4.2 | D28: 78.65 | F28: =IF(COUNT(B28:C28)=2,C28-B28,"") | G28: Needs review | H28: Mughsayl HTML demo — DUMMY DATA, not an approved report | I28: Dummy programme; future actuals intentionally blank.
A29: 46447 | B29: 3.8 | D29: 82.45 | F29: =IF(COUNT(B29:C29)=2,C29-B29,"") | G29: Needs review | H29: Mughsayl HTML demo — DUMMY DATA, not an approved report | I29: Dummy programme; future actuals intentionally blank.
A30: 46478 | B30: 3.5 | D30: 85.95 | F30: =IF(COUNT(B30:C30)=2,C30-B30,"") | G30: Needs review | H30: Mughsayl HTML demo — DUMMY DATA, not an approved report | I30: Dummy programme; future actuals intentionally blank.
A31: 46508 | B31: 3 | D31: 88.95 | F31: =IF(COUNT(B31:C31)=2,C31-B31,"") | G31: Needs review | H31: Mughsayl HTML demo — DUMMY DATA, not an approved report | I31: Dummy programme; future actuals intentionally blank.
A32: 46539 | B32: 2.5 | D32: 91.45 | F32: =IF(COUNT(B32:C32)=2,C32-B32,"") | G32: Needs review | H32: Mughsayl HTML demo — DUMMY DATA, not an approved report | I32: Dummy programme; future actuals intentionally blank.
A33: 46569 | B33: 2 | D33: 93.45 | F33: =IF(COUNT(B33:C33)=2,C33-B33,"") | G33: Needs review | H33: Mughsayl HTML demo — DUMMY DATA, not an approved report | I33: Dummy programme; future actuals intentionally blank.
A34: 46600 | B34: 6.55 | D34: 100 | F34: =IF(COUNT(B34:C34)=2,C34-B34,"") | G34: Needs review | H34: Mughsayl HTML demo — DUMMY DATA, not an approved report | I34: Dummy programme; future actuals intentionally blank.
F35: =IF(COUNT(B35:C35)=2,C35-B35,"")
F36: =IF(COUNT(B36:C36)=2,C36-B36,"")
F37: =IF(COUNT(B37:C37)=2,C37-B37,"")
F38: =IF(COUNT(B38:C38)=2,C38-B38,"")
F39: =IF(COUNT(B39:C39)=2,C39-B39,"")
F40: =IF(COUNT(B40:C40)=2,C40-B40,"")
F41: =IF(COUNT(B41:C41)=2,C41-B41,"")
F42: =IF(COUNT(B42:C42)=2,C42-B42,"")
F43: =IF(COUNT(B43:C43)=2,C43-B43,"")
F44: =IF(COUNT(B44:C44)=2,C44-B44,"")
F45: =IF(COUNT(B45:C45)=2,C45-B45,"")
...

Sheet Resources
A1: Contractor resources
A2: Whole-number counts. Negative variance means actual resources below plan.
A3: Resource | B3: Planned | C3: Actual | D3: Calculated actual-plan | E3: Printed variance | F3: Unit | G3: Entry status | H3: Source reference | I3: Notes
A4: Machinery | B4: 126 | C4: 110 | D4: =IF(COUNT(B4:C4)=2,C4-B4,"") | E4: -16 | F4: units | G4: Needs review | H4: Mughsayl HTML demo — DUMMY DATA, not an approved report
A5: Manpower | B5: 310 | C5: 290 | D5: =IF(COUNT(B5:C5)=2,C5-B5,"") | E5: -20 | F5: persons | G5: Needs review | H5: Mughsayl HTML demo — DUMMY DATA, not an approved report

Sheet Scope_Layers
A1: Scope quantities and pavement layers
A2: Optional sections: type Scope or Layer. Layer thickness is separate from scope quantity. Blank means not reported.
A3: Type | B3: Stable ID / layer code | C3: Description | D3: Quantity | E3: Unit | F3: Thickness mm | G3: Qualifier / notes | H3: Entry status | I3: Source reference
A4: Scope | B4: scope_01 | C4: Asphalt road length | D4: 28.09 | E4: km | H4: Needs review | I4: Mughsayl HTML demo — DUMMY DATA, not an approved report
A5: Scope | B5: scope_02 | C5: Salalah By-pass | D5: 5.521 | E5: km | H5: Needs review | I5: Mughsayl HTML demo — DUMMY DATA, not an approved report
A6: Scope | B6: scope_03 | C6: Under-passes | D6: 8 | E6: no. | H6: Needs review | I6: Mughsayl HTML demo — DUMMY DATA, not an approved report
A7: Scope | B7: scope_04 | C7: Flyover | D7: 1 | E7: no. | H7: Needs review | I7: Mughsayl HTML demo — DUMMY DATA, not an approved report
A8: Scope | B8: scope_05 | C8: Box culverts | D8: 82 | E8: no. | H8: Needs review | I8: Mughsayl HTML demo — DUMMY DATA, not an approved report
A9: Layer | B9: BWC | C9: Bituminous Wearing Course | F9: 50 | H9: Needs review | I9: Mughsayl HTML demo — DUMMY DATA, not an approved report
A10: Layer | B10: BBC | C10: Bituminous Base Course | F10: 60 | H10: Needs review | I10: Mughsayl HTML demo — DUMMY DATA, not an approved report
A11: Layer | B11: ABC | C11: Aggregate Base Course | F11: 300 | H11: Needs review | I11: Mughsayl HTML demo — DUMMY DATA, not an approved report
A12: Layer | B12: GSB | C12: Granular Sub-Base | F12: 200 | H12: Needs review | I12: Mughsayl HTML demo — DUMMY DATA, not an approved report
B13: item_10 | H13: Not reported
B14: item_11 | H14: Not reported
B15: item_12 | H15: Not reported
B16: item_13 | H16: Not reported
B17: item_14 | H17: Not reported
B18: item_15 | H18: Not reported

Sheet Status_Updates
A1: Narrative progress and independent trade status
A2: Preserve the source wording. For example, “in progress (76/76)” needs clarification, not automatic conversion to Complete.
A3: Update ID | B3: Description / source wording | C3: Explicit trade status | D3: Entry status | E3: Source reference | F3: Clarification / internal note
A4: update_01 | B4: Protection — cut slope | C4: Active | D4: Needs review | E4: Mughsayl HTML demo — DUMMY DATA, not an approved report | F4: Dummy trade status
A5: update_02 | B5: Utilities | C5: Active | D5: Needs review | E5: Mughsayl HTML demo — DUMMY DATA, not an approved report | F5: Dummy trade status
A6: update_03 | B6: Land acquisition | C6: Complete | D6: Needs review | E6: Mughsayl HTML demo — DUMMY DATA, not an approved report | F6: Dummy trade status
A7: update_04 | B7: Culverts / retaining walls | C7: Complete | D7: Needs review | E7: Mughsayl HTML demo — DUMMY DATA, not an approved report | F7: Dummy trade status
A8: update_05 | B8: Bridges / tunnels | C8: Active | D8: Needs review | E8: Mughsayl HTML demo — DUMMY DATA, not an approved report | F8: Dummy trade status
A9: update_06 | B9: Pedestrian over/underpass | C9: Active | D9: Needs review | E9: Mughsayl HTML demo — DUMMY DATA, not an approved report | F9: Dummy trade status
A10: update_07 | B10: Earthworks | C10: Complete | D10: Needs review | E10: Mughsayl HTML demo — DUMMY DATA, not an approved report | F10: Dummy trade status
A11: update_08 | B11: Subbase layer | C11: Behind | D11: Needs review | E11: Mughsayl HTML demo — DUMMY DATA, not an approved report | F11: Dummy trade status
A12: update_09 | B12: Aggregate base course | C12: Behind | D12: Needs review | E12: Mughsayl HTML demo — DUMMY DATA, not an approved report | F12: Dummy trade status
A13: update_10 | B13: Bit. base course | C13: Behind | D13: Needs review | E13: Mughsayl HTML demo — DUMMY DATA, not an approved report | F13: Dummy trade status
A14: update_11 | B14: Bit. wearing course | C14: Not started | D14: Needs review | E14: Mughsayl HTML demo — DUMMY DATA, not an approved report | F14: Dummy trade status
A15: update_12 | B15: Protection — embankment | C15: Active | D15: Needs review | E15: Mughsayl HTML demo — DUMMY DATA, not an approved report | F15: Dummy trade status
A16: update_13 | C16: Unknown | D16: Not reported
A17: update_14 | C17: Unknown | D17: Not reported
A18: update_15 | C18: Unknown | D18: Not reported
A19: update_16 | C19: Unknown | D19: Not reported
A20: update_17 | C20: Unknown | D20: Not reported
A21: update_18 | C21: Unknown | D21: Not reported
A22: update_19 | C22: Unknown | D22: Not reported
A23: update_20 | C23: Unknown | D23: Not reported

Sheet Contacts
A1: Project parties and contacts
A2: Enter telephone numbers as TEXT. Unclear small-print names and numbers were not guessed in the example.
A3: Party role | B3: Organisation | C3: Department | D3: Representative | E3: Position / title | F3: Telephone | G3: Email | H3: Entry status | I3: Source reference
A4: Client | B4: Example Transport Authority | C4: Roads & Land Transport | H4: Needs review | I4: Mughsayl HTML demo — DUMMY DATA, not an approved report
A5: Consultant | B5: VIA International — Engineering Consultancy | D5: Demo Resident Engineer | E5: Resident Engineer | F5: Demo contact | H5: Needs review | I5: Mughsayl HTML demo — DUMMY DATA, not an approved report
A6: Contractor | B6: Example Road & Bridge Contractor | D6: Demo Project Manager | E6: Project Manager | F6: Demo contact | H6: Needs review | I6: Mughsayl HTML demo — DUMMY DATA, not an approved report
A7: Client representative | D7: Demo Client Representative | F7: Demo contact | H7: Needs review | I7: Mughsayl HTML demo — DUMMY DATA, not an approved report
A8: Other contact | H8: Not reported

Sheet Assets
A1: Manual image uploads and captions
A2: Upload files separately in the app. Match using Asset ID, not filename guesses. Images are not embedded in this workbook.
A3: Asset ID | B3: Purpose | C3: Requirement | D3: Local filename | E3: Caption | F3: Secondary description | G3: Capture date | H3: Entry status | I3: Upload guidance
A4: logo_main | B4: Main dashboard logo | C4: Required | D4: Dashboard/via/logo-color.png | H4: Needs review | I4: JPG/PNG/WebP. Keep original resolution; do not upscale to imply extra detail.
A5: layout_main | B5: Location / project layout | C5: Required | D5: Dashboard/Raysut dashboard.html | E5: Raysut reference illustration — demo only | H5: Needs review | I5: Embedded vector schematic, not an uploaded image. Requires the Raysut reference-layout option; not transferable to another route.
A6: photo_1 | B6: Construction photo 1 | C6: Required | D6: Dashboard/Photo1.jpg | E6: Pier foundation backfill | F6: Reference photograph — demonstration only | H6: Needs review | I6: JPG/PNG/WebP. Keep original resolution; do not upscale to imply extra detail.
A7: photo_2 | B7: Construction photo 2 | C7: Required | D7: Dashboard/Photo2.jpg | E7: Bitumen base course layer | F7: Reference photograph — demonstration only | H7: Needs review | I7: JPG/PNG/WebP. Keep original resolution; do not upscale to imply extra detail.
A8: photo_3 | B8: Construction photo 3 | C8: Required | D8: Dashboard/Photo3.jpg | E8: Utilities future ducts | F8: Reference photograph — demonstration only | H8: Needs review | I8: JPG/PNG/WebP. Keep original resolution; do not upscale to imply extra detail.
A9: photo_4 | B9: Construction photo 4 | C9: Required | D9: Dashboard/Photo4.jpg | E9: I-girder work in progress | F9: Reference photograph — demonstration only | H9: Needs review | I9: JPG/PNG/WebP. Keep original resolution; do not upscale to imply extra detail.
A10: logo_client | B10: Additional client logo | C10: Optional | H10: Not reported | I10: JPG/PNG/WebP. Keep original resolution; do not upscale to imply extra detail.
A11: logo_contractor | B11: Additional contractor logo | C11: Optional | H11: Not reported | I11: JPG/PNG/WebP. Keep original resolution; do not upscale to imply extra detail.
A12: status_drawing | B12: Activity-status drawing | C12: If reported | H12: Not reported | I12: JPG/PNG/WebP. Keep original resolution; do not upscale to imply extra detail.
A13: s_curve | B13: Original S-curve image | C13: If chart table unreadable | H13: Not reported | I13: Interactive chart is populated from Monthly_Schedule, not a picture.

Sheet Checks
A1: Review checklist and calculated comparisons
A2: Checks are not a certification of accuracy. Formula results calculate when opened in Excel.
A3: Check | B3: Result | C3: Reviewer guidance
A4: Physical actual minus planned | B4: =IF(COUNT('Progress_Finance'!C5,'Progress_Finance'!C4)=2,'Progress_Finance'!C5-'Progress_Finance'!C4,"Not reported") | C4: Percentage points; compare with the printed physical variance.
A5: Financial actual minus planned | B5: =IF(COUNT('Progress_Finance'!C12,'Progress_Finance'!C11)=2,'Progress_Finance'!C12-'Progress_Finance'!C11,"Not reported") | C5: Sample result -4.39; source prints +4.39. Confirm convention.
A6: Elapsed + remaining - construction | B6: =IF(COUNT('Contract_Dates'!C21,'Contract_Dates'!C22,'Contract_Dates'!C16)=3,'Contract_Dates'!C21+'Contract_Dates'!C22-'Contract_Dates'!C16,"Not reported") | C6: Zero means reported durations reconcile. Sample: 636 + 33 = 669.
A7: Original including contingency minus components | B7: =IF(COUNT('Contract_Dates'!C7,'Contract_Dates'!C5,'Contract_Dates'!C6)=3,'Contract_Dates'!C7-'Contract_Dates'!C5-'Contract_Dates'!C6,"Not reported") | C7: Zero means monetary components reconcile.
A8: Days between original start and completion | B8: =IF(COUNT('Contract_Dates'!C18,'Contract_Dates'!C17)=2,'Contract_Dates'!C18-'Contract_Dates'!C17,"Not reported") | C8: Calendar subtraction, excluding the starting day. Compare with contractual counting rules, not an automatic error.
A9: Source schedule readability | B9: MANUAL CHECK | C9: Tiny chart table in sample was not transcribed. Supply original data or source image.
A10: Project identity and reporting month | B10: MANUAL CHECK | C10: Confirm uploaded PDF, workbook and selected existing project all match.
A11: Images and captions | B11: MANUAL CHECK | C11: Check main logo, layout, all four photos and any supplemental drawings.
A12: Publication approval | B12: NOT APPROVED — DUMMY DATA | C12: Preview and approve inside the app after resolving all required fields and review issues.
